<?xml version="1.0" encoding="UTF-8"?>
<!-- Generated by org.testng.reporters.JUnitReportReporter -->
<testsuite hostname="DESKTOP-02J8MEC" failures="1" tests="7" name="TestNgProject.TestNG.FailedTestCaseExample" time="0.014" errors="0" timestamp="2025-07-04T15:35:19 IST" skipped="4">
  <testcase classname="TestNgProject.TestNG.FailedTestCaseExample" name="Test2" time="0.000">
    <failure message="expected [true] but found [false]" type="java.lang.AssertionError">
      <![CDATA[java.lang.AssertionError: expected [true] but found [false]
at org.testng.Assert.fail(Assert.java:111)
at org.testng.Assert.failNotEquals(Assert.java:1590)
at org.testng.Assert.assertTrue(Assert.java:57)
at org.testng.Assert.assertTrue(Assert.java:67)
at TestNgProject.TestNG.FailedTestCaseExample.Test2(FailedTestCaseExample.java:15)
at java.base/jdk.internal.reflect.DirectMethodHandleAccessor.invoke(DirectMethodHandleAccessor.java:104)
at java.base/java.lang.reflect.Method.invoke(Method.java:565)
at org.testng.internal.invokers.MethodInvocationHelper.invokeMethod(MethodInvocationHelper.java:141)
at org.testng.internal.invokers.TestInvoker.invokeMethod(TestInvoker.java:687)
at org.testng.internal.invokers.TestInvoker.retryFailed(TestInvoker.java:269)
at org.testng.internal.invokers.MethodRunner.runInSequence(MethodRunner.java:76)
at org.testng.internal.invokers.TestInvoker$MethodInvocationAgent.invoke(TestInvoker.java:995)
at org.testng.internal.invokers.TestInvoker.invokeTestMethods(TestInvoker.java:203)
at org.testng.internal.invokers.TestMethodWorker.invokeTestMethods(TestMethodWorker.java:154)
at org.testng.internal.invokers.TestMethodWorker.run(TestMethodWorker.java:134)
at java.base/java.util.ArrayList.forEach(ArrayList.java:1604)
at org.testng.TestRunner.privateRun(TestRunner.java:741)
at org.testng.TestRunner.run(TestRunner.java:616)
at org.testng.SuiteRunner.runTest(SuiteRunner.java:421)
at org.testng.SuiteRunner.runSequentially(SuiteRunner.java:413)
at org.testng.SuiteRunner.privateRun(SuiteRunner.java:373)
at org.testng.SuiteRunner.run(SuiteRunner.java:312)
at org.testng.SuiteRunnerWorker.runSuite(SuiteRunnerWorker.java:52)
at org.testng.SuiteRunnerWorker.run(SuiteRunnerWorker.java:95)
at org.testng.TestNG.runSuitesSequentially(TestNG.java:1274)
at org.testng.TestNG.runSuitesLocally(TestNG.java:1208)
at org.testng.TestNG.runSuites(TestNG.java:1112)
at org.testng.TestNG.run(TestNG.java:1079)
at com.intellij.rt.testng.IDEARemoteTestNG.run(IDEARemoteTestNG.java:65)
at com.intellij.rt.testng.RemoteTestNGStarter.main(RemoteTestNGStarter.java:105)
]]>
    </failure>
  </testcase> <!-- Test2 -->
  <testcase classname="TestNgProject.TestNG.FailedTestCaseExample" name="Test1" time="0.006"/>
  <testcase classname="TestNgProject.TestNG.FailedTestCaseExample" name="Test3" time="0.001"/>
  <testcase classname="TestNgProject.TestNG.FailedTestCaseExample" name="Test2" time="0.005">
    <skipped/>
  </testcase> <!-- Test2 -->
  <testcase classname="TestNgProject.TestNG.FailedTestCaseExample" name="Test2" time="0.001">
    <skipped/>
  </testcase> <!-- Test2 -->
  <testcase classname="TestNgProject.TestNG.FailedTestCaseExample" name="Test2" time="0.000">
    <skipped/>
  </testcase> <!-- Test2 -->
  <testcase classname="TestNgProject.TestNG.FailedTestCaseExample" name="Test2" time="0.001">
    <skipped/>
  </testcase> <!-- Test2 -->
</testsuite> <!-- TestNgProject.TestNG.FailedTestCaseExample -->
